2017-11-01 20:59:52,575 [ALWAYS] mongo_connector.connector:51 - Starting mongo-connector version: 2.5.1
2017-11-01 20:59:52,577 [ALWAYS] mongo_connector.connector:51 - Python version: 3.6.3 (v3.6.3:2c5fed8, Oct  3 2017, 17:26:49) [MSC v.1900 32 bit (Intel)]
2017-11-01 20:59:52,579 [ALWAYS] mongo_connector.connector:51 - Platform: Windows-10-10.0.14393-SP0
2017-11-01 20:59:52,579 [ALWAYS] mongo_connector.connector:51 - pymongo version: 3.5.1
2017-11-01 20:59:52,581 [WARNING] mongo_connector.connector:167 - MongoConnector: Can't find C:\ashif\Configurations\mongo-connector\logs\oplog.timestamp, attempting to create an empty progress log
2017-11-01 20:59:52,628 [ALWAYS] mongo_connector.connector:51 - Source MongoDB version: 3.4.4
2017-11-01 20:59:52,629 [ALWAYS] mongo_connector.connector:51 - Target DocManager: mongo_connector.doc_managers.elastic2_doc_manager version: 0.3.0
2017-11-01 21:21:01,660 [ERROR] mongo_connector.util:106 - Fatal Exception
Traceback (most recent call last):
  File "c:\users\administrator\appdata\local\programs\python\python36-32\lib\site-packages\mongo_connector\util.py", line 104, in wrapped
    func(*args, **kwargs)
  File "c:\users\administrator\appdata\local\programs\python\python36-32\lib\site-packages\mongo_connector\connector.py", line 404, in run
    self.write_oplog_progress()
  File "c:\users\administrator\appdata\local\programs\python\python36-32\lib\site-packages\mongo_connector\connector.py", line 246, in write_oplog_progress
    os.rename(self.oplog_checkpoint, backup_file)
PermissionError: [WinError 32] The process cannot access the file because it is being used by another process: 'C:\\ashif\\Configurations\\mongo-connector\\logs\\oplog.timestamp' -> 'C:\\ashif\\Configurations\\mongo-connector\\logs\\oplog.timestamp.backup'
